import { Request, Response, NextFunction } from "express";
import ErrorHandler from "../utils/ErrorHandler";
import CatchAsyncError from "../middleware/CatchAsyncError";
import { generateYearlyData } from "../utils/analytics.generator";
import userModel from "../models/user.model";
import CourseModel from "../models/course.model";
import OrderModel from "../models/order.model";

export const getUsersAnalytics = CatchAsyncError(
  async (req: Request, res: Response, next: NextFunction) => {
    try {
      const users = await generateYearlyData(userModel);
      res.status(200).json({
        success: true,
        users,
      });
    } catch (error: any) {
      return next(new ErrorHandler(error.message, 400));
    }
  }
);

export const getCoursesAnalytics = CatchAsyncError(
  async (req: Request, res: Response, next: NextFunction) => {
    try {
      const courses = await generateYearlyData(CourseModel);
      res.status(200).json({
        success: true,
        courses,
      });
    } catch (error: any) {
      return next(new ErrorHandler(error.message, 400));
    }
  }
);

export const getOrdersAnalytics = CatchAsyncError(
  async (req: Request, res: Response, next: NextFunction) => {
    try {
      const orders = await generateYearlyData(OrderModel);
      res.status(200).json({
        success: true,
        orders,
      });
    } catch (error: any) {
      return next(new ErrorHandler(error.message, 400));
    }
  }
);
